Traceback (most recent call last):
  File "fit_line_mdwarf_200_1.py", line 114, in <module>
    num_boot = cpu_count(), cores = cpu_count())
  File "/storage/work/s/szk381/mrexo/mrexo/fit.py", line 177, in fit_mr_relation
    
  File "/storage/work/s/szk381/mrexo/mrexo/cross_validate.py", line 71, in run_cross_validation
    np.savetxt(os.path.join(save_path,'likelihood_per_degree.txt'),np.array([degree_candidates,likelihood_per_degree]))
  File "/storage/home/szk381/.conda/envs/pyvenv/lib/python2.7/site-packages/numpy/lib/npyio.py", line 1318, in savetxt
    fh = np.lib._datasource.open(fname, 'wt', encoding=encoding)
  File "/storage/home/szk381/.conda/envs/pyvenv/lib/python2.7/site-packages/numpy/lib/_datasource.py", line 261, in open
    ds = DataSource(destpath)
  File "/storage/home/szk381/.conda/envs/pyvenv/lib/python2.7/site-packages/numpy/lib/_datasource.py", line 317, in __init__
    self._destpath = os.path.abspath(destpath)
  File "/storage/home/szk381/.conda/envs/pyvenv/lib/python2.7/posixpath.py", line 364, in abspath
    cwd = os.getcwd()
OSError: [Errno 2] No such file or directory
Exception AttributeError: "'DataSource' object has no attribute '_istmpdest'" in <bound method DataSource.__del__ of <numpy.lib._datasource.DataSource object at 0x2ab2c9c87f10>> ignored
