Traceback (most recent call last):
  File "sample_fit.py", line 13, in <module>
    t = Table.read(os.path.join(pwd,'Cool_stars_MR_20181214_exc_upperlim.csv'))
  File "/storage/home/szk381/.conda/envs/pyvenv/lib/python2.7/site-packages/astropy/table/table.py", line 2521, in read
    out = io_registry.read(cls, *args, **kwargs)
  File "/storage/home/szk381/.conda/envs/pyvenv/lib/python2.7/site-packages/astropy/io/registry.py", line 516, in read
    fileobj = ctx.__enter__()
  File "/storage/home/szk381/.conda/envs/pyvenv/lib/python2.7/contextlib.py", line 17, in __enter__
    return self.gen.next()
  File "/storage/home/szk381/.conda/envs/pyvenv/lib/python2.7/site-packages/astropy/utils/data.py", line 206, in get_readable_fileobj
    fileobj = open(name_or_obj, 'rb')
IOError: [Errno 2] No such file or directory: 'Cool_stars_MR_20181214_exc_upperlim.csv'
